Workbook

Sheet INSTRUCTIONS
A1: 🏆 PANINI FIFA WORLD CUP 2026 — TRACKER Welcome to the Panini FIFA World Cup 2026 album tracking system. 📋 How to use this file 1. Make a copy of the file This file is a public template. To use it properly: File → Make a copy ━━━━━━━━━━━━━━━━━━━━━━ ✏️ What should I edit? Only modify the: QUANTITY column in the album tabs: • 01_PANINI • 02_GROUP_A • 03_GROUP_B • 04_GROUP_C • 05_GROUP_D • 06_GROUP_E • 07_GROUP_F • 08_COCA_COLA_STICKERS • 09_GROUP_G • 10_GROUP_H • 11_GROUP_I • 12_GROUP_J • 13_GROUP_K • 14_GROUP_L • 15_FIFA_WORLD_CUP_CHAMPIONS ━━━━━━━━━━━━━━━━━━━━━━ 🔢 How does QUANTITY work? 0 = You do not own it 1 = You own it 2 or more = Duplicates ━━━━━━━━━━━━━━━━━━━━━━ 📊 What does the system calculate automatically? The file automatically calculates: ✅ Total stickers ✅ Album completion progress ✅ Missing stickers ✅ Duplicate stickers ✅ Total duplicates ━━━━━━━━━━━━━━━━━━━━━━ 🔒 Protected sheets The following sheets work automatically and should not be edited: • MASTER • DASHBOARD • MISSING • TRADING ━━━━━━━━━━━━━━━━━━━━━━ 🤝 Project goal This file was designed to help Panini FIFA World Cup 2026 collectors keep accurate, fast, and scalable control of their collection. ━━━━━━━━━━━━━━━━━━━━━━ ⚽ Enjoy the album!

Sheet DASHBOARD
A1: TOTAL DE ESTAMPAS | B1: =COUNTA(MASTER!A2:A1000) -> 994
A2: ESTAMPAS QUE TENGO | B2: =SUM(MASTER!F2:F1000) -> 0
A3: ESTAMPAS FALTANTES | B3: =COUNTIF(MASTER!E2:E1000,"=0") -> 994
A4: ESTAMPAS REPETIDAS | B4: =COUNTIF(MASTER!E2:E1000,">1") -> 0
A5: TOTAL DE REPETIDAS | B5: =SUMPRODUCT(IF(MASTER!E2:E1000>1, MASTER!E2:E1000-1, 0)) -> 0
A6: PORCENTAJE DE AVANCE | B6: =SUM(MASTER!F2:F1000) / COUNTA(MASTER!A2:A1000) -> 0

Sheet MASTER
A1: ID | B1: CONTEXT | C1: TYPE | D1: DESCRIPTION | E1: QUANTITY | F1: OWNED
A2: =IFERROR(__xludf.DUMMYFUNCTION("FILTER({'01_PANINI'!A2:E1000,IF('01_PANINI'!E2:E1000>0,1,0);'02_GRUPO_A'!A2:E1000,IF('02_GRUPO_A'!E2:E1000>0,1,0);'03_GRUPO_B'!A2:E1000,IF('03_GRUPO_B'!E2:E1000>0,1,0);'04_GRUPO_C'!A2:E1000,IF('04_GRUPO_C'!E2:E1000>0,1,0);'05_GRUPO_D'!A2:E1000,IF('05_GRUP"&"O_D'!E2:E1000>0,1,0);'06_GRUPO_E'!A2:E1000,IF('06_GRUPO_E'!E2:E1000>0,1,0);'07_GRUPO_F'!A2:E1000,IF('07_GRUPO_F'!E2:E1000>0,1,0);'08_STICKERS_COCA_COLA'!A2:E1000,IF('08_STICKERS_COCA_COLA'!E2:E1000>0,1,0);'09_GRUPO_G'!A2:E1000,IF('09_GRUPO_G'!E2:E1000>0,1"&",0);'10_GRUPO_H'!A2:E1000,IF('10_GRUPO_H'!E2:E1000>0,1,0);'11_GRUPO_I'!A2:E1000,IF('11_GRUPO_I'!E2:E1000>0,1,0);'12_GRUPO_J'!A2:E1000,IF('12_GRUPO_J'!E2:E1000>0,1,0);'13_GRUPO_K'!A2:E1000,IF('13_GRUPO_K'!E2:E1000>0,1,0);'14_GRUPO_L'!A2:E1000,IF('14_GRUPO_"&"L'!E2:E1000>0,1,0);'15_FIFA_WORLD_CUP_CHAMPIONS'!A2:E1000,IF('15_FIFA_WORLD_CUP_CHAMPIONS'!E2:E1000>0,1,0)},INDEX({'01_PANINI'!A2:A1000;'02_GRUPO_A'!A2:A1000;'03_GRUPO_B'!A2:A1000;'04_GRUPO_C'!A2:A1000;'05_GRUPO_D'!A2:A1000;'06_GRUPO_E'!A2:A1000;'07_GRUPO"&"_F'!A2:A1000;'08_STICKERS_COCA_COLA'!A2:A1000;'09_GRUPO_G'!A2:A1000;'10_GRUPO_H'!A2:A1000;'11_GRUPO_I'!A2:A1000;'12_GRUPO_J'!A2:A1000;'13_GRUPO_K'!A2:A1000;'14_GRUPO_L'!A2:A1000;'15_FIFA_WORLD_CUP_CHAMPIONS'!A2:A1000})<>"""")"),"00") -> 00 | B2: =IFERROR(__xludf.DUMMYFUNCTION("""COMPUTED_VALUE"""),"SECTION 1") -> SECTION 1 | C2: =IFERROR(__xludf.DUMMYFUNCTION("""COMPUTED_VALUE"""),"SPECIAL") -> SPECIAL | D2: =IFERROR(__xludf.DUMMYFUNCTION("""COMPUTED_VALUE"""),"WE ARE PANINI") -> WE ARE PANINI | E2: =IFERROR(__xludf.DUMMYFUNCTION("""COMPUTED_VALUE"""),0.0) -> 0 | F2: =IFERROR(__xludf.DUMMYFUNCTION("""COMPUTED_VALUE"""),0.0) -> 0
A3: =IFERROR(__xludf.DUMMYFUNCTION("""COMPUTED_VALUE"""),"FWC1") -> FWC1 | B3: =IFERROR(__xludf.DUMMYFUNCTION("""COMPUTED_VALUE"""),"SECTION 1") -> SECTION 1 | C3: =IFERROR(__xludf.DUMMYFUNCTION("""COMPUTED_VALUE"""),"SPECIAL") -> SPECIAL | D3: =IFERROR(__xludf.DUMMYFUNCTION("""COMPUTED_VALUE"""),"FWC 1") -> FWC 1 | E3: =IFERROR(__xludf.DUMMYFUNCTION("""COMPUTED_VALUE"""),0.0) -> 0 | F3: =IFERROR(__xludf.DUMMYFUNCTION("""COMPUTED_VALUE"""),0.0) -> 0
A4: =IFERROR(__xludf.DUMMYFUNCTION("""COMPUTED_VALUE"""),"FWC2") -> FWC2 | B4: =IFERROR(__xludf.DUMMYFUNCTION("""COMPUTED_VALUE"""),"SECTION 1") -> SECTION 1 | C4: =IFERROR(__xludf.DUMMYFUNCTION("""COMPUTED_VALUE"""),"SPECIAL") -> SPECIAL | D4: =IFERROR(__xludf.DUMMYFUNCTION("""COMPUTED_VALUE"""),"FWC 2") -> FWC 2 | E4: =IFERROR(__xludf.DUMMYFUNCTION("""COMPUTED_VALUE"""),0.0) -> 0 | F4: =IFERROR(__xludf.DUMMYFUNCTION("""COMPUTED_VALUE"""),0.0) -> 0
A5: =IFERROR(__xludf.DUMMYFUNCTION("""COMPUTED_VALUE"""),"FWC3") -> FWC3 | B5: =IFERROR(__xludf.DUMMYFUNCTION("""COMPUTED_VALUE"""),"SECTION 1") -> SECTION 1 | C5: =IFERROR(__xludf.DUMMYFUNCTION("""COMPUTED_VALUE"""),"SPECIAL") -> SPECIAL | D5: =IFERROR(__xludf.DUMMYFUNCTION("""COMPUTED_VALUE"""),"FWC 3") -> FWC 3 | E5: =IFERROR(__xludf.DUMMYFUNCTION("""COMPUTED_VALUE"""),0.0) -> 0 | F5: =IFERROR(__xludf.DUMMYFUNCTION("""COMPUTED_VALUE"""),0.0) -> 0
A6: =IFERROR(__xludf.DUMMYFUNCTION("""COMPUTED_VALUE"""),"FWC4") -> FWC4 | B6: =IFERROR(__xludf.DUMMYFUNCTION("""COMPUTED_VALUE"""),"SECTION 1") -> SECTION 1 | C6: =IFERROR(__xludf.DUMMYFUNCTION("""COMPUTED_VALUE"""),"SPECIAL") -> SPECIAL | D6: =IFERROR(__xludf.DUMMYFUNCTION("""COMPUTED_VALUE"""),"FWC 4") -> FWC 4 | E6: =IFERROR(__xludf.DUMMYFUNCTION("""COMPUTED_VALUE"""),0.0) -> 0 | F6: =IFERROR(__xludf.DUMMYFUNCTION("""COMPUTED_VALUE"""),0.0) -> 0
A7: =IFERROR(__xludf.DUMMYFUNCTION("""COMPUTED_VALUE"""),"FWC5") -> FWC5 | B7: =IFERROR(__xludf.DUMMYFUNCTION("""COMPUTED_VALUE"""),"SECTION 1") -> SECTION 1 | C7: =IFERROR(__xludf.DUMMYFUNCTION("""COMPUTED_VALUE"""),"SPECIAL") -> SPECIAL | D7: =IFERROR(__xludf.DUMMYFUNCTION("""COMPUTED_VALUE"""),"FWC 5") -> FWC 5 | E7: =IFERROR(__xludf.DUMMYFUNCTION("""COMPUTED_VALUE"""),0.0) -> 0 | F7: =IFERROR(__xludf.DUMMYFUNCTION("""COMPUTED_VALUE"""),0.0) -> 0
A8: =IFERROR(__xludf.DUMMYFUNCTION("""COMPUTED_VALUE"""),"FWC6") -> FWC6 | B8: =IFERROR(__xludf.DUMMYFUNCTION("""COMPUTED_VALUE"""),"SECTION 1") -> SECTION 1 | C8: =IFERROR(__xludf.DUMMYFUNCTION("""COMPUTED_VALUE"""),"SPECIAL") -> SPECIAL | D8: =IFERROR(__xludf.DUMMYFUNCTION("""COMPUTED_VALUE"""),"FWC 6") -> FWC 6 | E8: =IFERROR(__xludf.DUMMYFUNCTION("""COMPUTED_VALUE"""),0.0) -> 0 | F8: =IFERROR(__xludf.DUMMYFUNCTION("""COMPUTED_VALUE"""),0.0) -> 0
A9: =IFERROR(__xludf.DUMMYFUNCTION("""COMPUTED_VALUE"""),"FWC7") -> FWC7 | B9: =IFERROR(__xludf.DUMMYFUNCTION("""COMPUTED_VALUE"""),"SECTION 1") -> SECTION 1 | C9: =IFERROR(__xludf.DUMMYFUNCTION("""COMPUTED_VALUE"""),"SPECIAL") -> SPECIAL | D9: =IFERROR(__xludf.DUMMYFUNCTION("""COMPUTED_VALUE"""),"FWC 7") -> FWC 7 | E9: =IFERROR(__xludf.DUMMYFUNCTION("""COMPUTED_VALUE"""),0.0) -> 0 | F9: =IFERROR(__xludf.DUMMYFUNCTION("""COMPUTED_VALUE"""),0.0) -> 0
A10: =IFERROR(__xludf.DUMMYFUNCTION("""COMPUTED_VALUE"""),"FWC8") -> FWC8 | B10: =IFERROR(__xludf.DUMMYFUNCTION("""COMPUTED_VALUE"""),"SECTION 1") -> SECTION 1 | C10: =IFERROR(__xludf.DUMMYFUNCTION("""COMPUTED_VALUE"""),"SPECIAL") -> SPECIAL | D10: =IFERROR(__xludf.DUMMYFUNCTION("""COMPUTED_VALUE"""),"FWC 8") -> FWC 8 | E10: =IFERROR(__xludf.DUMMYFUNCTION("""COMPUTED_VALUE"""),0.0) -> 0 | F10: =IFERROR(__xludf.DUMMYFUNCTION("""COMPUTED_VALUE"""),0.0) -> 0
A11: =IFERROR(__xludf.DUMMYFUNCTION("""COMPUTED_VALUE"""),"MEX01") -> MEX01 | B11: =IFERROR(__xludf.DUMMYFUNCTION("""COMPUTED_VALUE"""),"MEXICO") -> MEXICO | C11: =IFERROR(__xludf.DUMMYFUNCTION("""COMPUTED_VALUE"""),"BADGE") -> BADGE | D11: =IFERROR(__xludf.DUMMYFUNCTION("""COMPUTED_VALUE"""),"MEXICO NATIONAL TEAM") -> MEXICO NATIONAL TEAM | E11: =IFERROR(__xludf.DUMMYFUNCTION("""COMPUTED_VALUE"""),0.0) -> 0 | F11: =IFERROR(__xludf.DUMMYFUNCTION("""COMPUTED_VALUE"""),0.0) -> 0
A12: =IFERROR(__xludf.DUMMYFUNCTION("""COMPUTED_VALUE"""),"MEX02") -> MEX02 | B12: =IFERROR(__xludf.DUMMYFUNCTION("""COMPUTED_VALUE"""),"MEXICO") -> MEXICO | C12: =IFERROR(__xludf.DUMMYFUNCTION("""COMPUTED_VALUE"""),"NORMAL") -> NORMAL | D12: =IFERROR(__xludf.DUMMYFUNCTION("""COMPUTED_VALUE"""),"LUIS MALAGÓN") -> LUIS MALAGÓN | E12: =IFERROR(__xludf.DUMMYFUNCTION("""COMPUTED_VALUE"""),0.0) -> 0 | F12: =IFERROR(__xludf.DUMMYFUNCTION("""COMPUTED_VALUE"""),0.0) -> 0
A13: =IFERROR(__xludf.DUMMYFUNCTION("""COMPUTED_VALUE"""),"MEX03") -> MEX03 | B13: =IFERROR(__xludf.DUMMYFUNCTION("""COMPUTED_VALUE"""),"MEXICO") -> MEXICO | C13: =IFERROR(__xludf.DUMMYFUNCTION("""COMPUTED_VALUE"""),"NORMAL") -> NORMAL | D13: =IFERROR(__xludf.DUMMYFUNCTION("""COMPUTED_VALUE"""),"JOHAN VÁSQUEZ") -> JOHAN VÁSQUEZ | E13: =IFERROR(__xludf.DUMMYFUNCTION("""COMPUTED_VALUE"""),0.0) -> 0 | F13: =IFERROR(__xludf.DUMMYFUNCTION("""COMPUTED_VALUE"""),0.0) -> 0
A14: =IFERROR(__xludf.DUMMYFUNCTION("""COMPUTED_VALUE"""),"MEX04") -> MEX04 | B14: =IFERROR(__xludf.DUMMYFUNCTION("""COMPUTED_VALUE"""),"MEXICO") -> MEXICO | C14: =IFERROR(__xludf.DUMMYFUNCTION("""COMPUTED_VALUE"""),"NORMAL") -> NORMAL | D14: =IFERROR(__xludf.DUMMYFUNCTION("""COMPUTED_VALUE"""),"JORGE SÁNCHEZ") -> JORGE SÁNCHEZ | E14: =IFERROR(__xludf.DUMMYFUNCTION("""COMPUTED_VALUE"""),0.0) -> 0 | F14: =IFERROR(__xludf.DUMMYFUNCTION("""COMPUTED_VALUE"""),0.0) -> 0
A15: =IFERROR(__xludf.DUMMYFUNCTION("""COMPUTED_VALUE"""),"MEX05") -> MEX05 | B15: =IFERROR(__xludf.DUMMYFUNCTION("""COMPUTED_VALUE"""),"MEXICO") -> MEXICO | C15: =IFERROR(__xludf.DUMMYFUNCTION("""COMPUTED_VALUE"""),"NORMAL") -> NORMAL | D15: =IFERROR(__xludf.DUMMYFUNCTION("""COMPUTED_VALUE"""),"CÉSAR MONTES") -> CÉSAR MONTES | E15: =IFERROR(__xludf.DUMMYFUNCTION("""COMPUTED_VALUE"""),0.0) -> 0 | F15: =IFERROR(__xludf.DUMMYFUNCTION("""COMPUTED_VALUE"""),0.0) -> 0
A16: =IFERROR(__xludf.DUMMYFUNCTION("""COMPUTED_VALUE"""),"MEX06") -> MEX06 | B16: =IFERROR(__xludf.DUMMYFUNCTION("""COMPUTED_VALUE"""),"MEXICO") -> MEXICO | C16: =IFERROR(__xludf.DUMMYFUNCTION("""COMPUTED_VALUE"""),"NORMAL") -> NORMAL | D16: =IFERROR(__xludf.DUMMYFUNCTION("""COMPUTED_VALUE"""),"JESÚS GALLARDO") -> JESÚS GALLARDO | E16: =IFERROR(__xludf.DUMMYFUNCTION("""COMPUTED_VALUE"""),0.0) -> 0 | F16: =IFERROR(__xludf.DUMMYFUNCTION("""COMPUTED_VALUE"""),0.0) -> 0
A17: =IFERROR(__xludf.DUMMYFUNCTION("""COMPUTED_VALUE"""),"MEX07") -> MEX07 | B17: =IFERROR(__xludf.DUMMYFUNCTION("""COMPUTED_VALUE"""),"MEXICO") -> MEXICO | C17: =IFERROR(__xludf.DUMMYFUNCTION("""COMPUTED_VALUE"""),"NORMAL") -> NORMAL | D17: =IFERROR(__xludf.DUMMYFUNCTION("""COMPUTED_VALUE"""),"ISRAEL REYES") -> ISRAEL REYES | E17: =IFERROR(__xludf.DUMMYFUNCTION("""COMPUTED_VALUE"""),0.0) -> 0 | F17: =IFERROR(__xludf.DUMMYFUNCTION("""COMPUTED_VALUE"""),0.0) -> 0
A18: =IFERROR(__xludf.DUMMYFUNCTION("""COMPUTED_VALUE"""),"MEX08") -> MEX08 | B18: =IFERROR(__xludf.DUMMYFUNCTION("""COMPUTED_VALUE"""),"MEXICO") -> MEXICO | C18: =IFERROR(__xludf.DUMMYFUNCTION("""COMPUTED_VALUE"""),"NORMAL") -> NORMAL | D18: =IFERROR(__xludf.DUMMYFUNCTION("""COMPUTED_VALUE"""),"DIEGO LAINEZ") -> DIEGO LAINEZ | E18: =IFERROR(__xludf.DUMMYFUNCTION("""COMPUTED_VALUE"""),0.0) -> 0 | F18: =IFERROR(__xludf.DUMMYFUNCTION("""COMPUTED_VALUE"""),0.0) -> 0
A19: =IFERROR(__xludf.DUMMYFUNCTION("""COMPUTED_VALUE"""),"MEX09") -> MEX09 | B19: =IFERROR(__xludf.DUMMYFUNCTION("""COMPUTED_VALUE"""),"MEXICO") -> MEXICO | C19: =IFERROR(__xludf.DUMMYFUNCTION("""COMPUTED_VALUE"""),"NORMAL") -> NORMAL | D19: =IFERROR(__xludf.DUMMYFUNCTION("""COMPUTED_VALUE"""),"CARLOS RODRÍGUEZ") -> CARLOS RODRÍGUEZ | E19: =IFERROR(__xludf.DUMMYFUNCTION("""COMPUTED_VALUE"""),0.0) -> 0 | F19: =IFERROR(__xludf.DUMMYFUNCTION("""COMPUTED_VALUE"""),0.0) -> 0
A20: =IFERROR(__xludf.DUMMYFUNCTION("""COMPUTED_VALUE"""),"MEX10") -> MEX10 | B20: =IFERROR(__xludf.DUMMYFUNCTION("""COMPUTED_VALUE"""),"MEXICO") -> MEXICO | C20: =IFERROR(__xludf.DUMMYFUNCTION("""COMPUTED_VALUE"""),"NORMAL") -> NORMAL | D20: =IFERROR(__xludf.DUMMYFUNCTION("""COMPUTED_VALUE"""),"EDSON ÁLVAREZ") -> EDSON ÁLVAREZ | E20: =IFERROR(__xludf.DUMMYFUNCTION("""COMPUTED_VALUE"""),0.0) -> 0 | F20: =IFERROR(__xludf.DUMMYFUNCTION("""COMPUTED_VALUE"""),0.0) -> 0
A21: =IFERROR(__xludf.DUMMYFUNCTION("""COMPUTED_VALUE"""),"MEX11") -> MEX11 | B21: =IFERROR(__xludf.DUMMYFUNCTION("""COMPUTED_VALUE"""),"MEXICO") -> MEXICO | C21: =IFERROR(__xludf.DUMMYFUNCTION("""COMPUTED_VALUE"""),"NORMAL") -> NORMAL | D21: =IFERROR(__xludf.DUMMYFUNCTION("""COMPUTED_VALUE"""),"ORBELÍN PINEDA") -> ORBELÍN PINEDA | E21: =IFERROR(__xludf.DUMMYFUNCTION("""COMPUTED_VALUE"""),0.0) -> 0 | F21: =IFERROR(__xludf.DUMMYFUNCTION("""COMPUTED_VALUE"""),0.0) -> 0
A22: =IFERROR(__xludf.DUMMYFUNCTION("""COMPUTED_VALUE"""),"MEX12") -> MEX12 | B22: =IFERROR(__xludf.DUMMYFUNCTION("""COMPUTED_VALUE"""),"MEXICO") -> MEXICO | C22: =IFERROR(__xludf.DUMMYFUNCTION("""COMPUTED_VALUE"""),"NORMAL") -> NORMAL | D22: =IFERROR(__xludf.DUMMYFUNCTION("""COMPUTED_VALUE"""),"MARCEL RUÍZ") -> MARCEL RUÍZ | E22: =IFERROR(__xludf.DUMMYFUNCTION("""COMPUTED_VALUE"""),0.0) -> 0 | F22: =IFERROR(__xludf.DUMMYFUNCTION("""COMPUTED_VALUE"""),0.0) -> 0
A23: =IFERROR(__xludf.DUMMYFUNCTION("""COMPUTED_VALUE"""),"MEX13") -> MEX13 | B23: =IFERROR(__xludf.DUMMYFUNCTION("""COMPUTED_VALUE"""),"MEXICO") -> MEXICO | C23: =IFERROR(__xludf.DUMMYFUNCTION("""COMPUTED_VALUE"""),"TEAM") -> TEAM | D23: =IFERROR(__xludf.DUMMYFUNCTION("""COMPUTED_VALUE"""),"MEXICO NATIONAL TEAM") -> MEXICO NATIONAL TEAM | E23: =IFERROR(__xludf.DUMMYFUNCTION("""COMPUTED_VALUE"""),0.0) -> 0 | F23: =IFERROR(__xludf.DUMMYFUNCTION("""COMPUTED_VALUE"""),0.0) -> 0
A24: =IFERROR(__xludf.DUMMYFUNCTION("""COMPUTED_VALUE"""),"MEX14") -> MEX14 | B24: =IFERROR(__xludf.DUMMYFUNCTION("""COMPUTED_VALUE"""),"MEXICO") -> MEXICO | C24: =IFERROR(__xludf.DUMMYFUNCTION("""COMPUTED_VALUE"""),"NORMAL") -> NORMAL | D24: =IFERROR(__xludf.DUMMYFUNCTION("""COMPUTED_VALUE"""),"ERICK SÁNCHEZ") -> ERICK SÁNCHEZ | E24: =IFERROR(__xludf.DUMMYFUNCTION("""COMPUTED_VALUE"""),0.0) -> 0 | F24: =IFERROR(__xludf.DUMMYFUNCTION("""COMPUTED_VALUE"""),0.0) -> 0
A25: =IFERROR(__xludf.DUMMYFUNCTION("""COMPUTED_VALUE"""),"MEX15") -> MEX15 | B25: =IFERROR(__xludf.DUMMYFUNCTION("""COMPUTED_VALUE"""),"MEXICO") -> MEXICO | C25: =IFERROR(__xludf.DUMMYFUNCTION("""COMPUTED_VALUE"""),"NORMAL") -> NORMAL | D25: =IFERROR(__xludf.DUMMYFUNCTION("""COMPUTED_VALUE"""),"HIRVING LOZANO") -> HIRVING LOZANO | E25: =IFERROR(__xludf.DUMMYFUNCTION("""COMPUTED_VALUE"""),0.0) -> 0 | F25: =IFERROR(__xludf.DUMMYFUNCTION("""COMPUTED_VALUE"""),0.0) -> 0
A26: =IFERROR(__xludf.DUMMYFUNCTION("""COMPUTED_VALUE"""),"MEX16") -> MEX16 | B26: =IFERROR(__xludf.DUMMYFUNCTION("""COMPUTED_VALUE"""),"MEXICO") -> MEXICO | C26: =IFERROR(__xludf.DUMMYFUNCTION("""COMPUTED_VALUE"""),"NORMAL") -> NORMAL | D26: =IFERROR(__xludf.DUMMYFUNCTION("""COMPUTED_VALUE"""),"SANTIAGO GIMÉNEZ") -> SANTIAGO GIMÉNEZ | E26: =IFERROR(__xludf.DUMMYFUNCTION("""COMPUTED_VALUE"""),0.0) -> 0 | F26: =IFERROR(__xludf.DUMMYFUNCTION("""COMPUTED_VALUE"""),0.0) -> 0
A27: =IFERROR(__xludf.DUMMYFUNCTION("""COMPUTED_VALUE"""),"MEX17") -> MEX17 | B27: =IFERROR(__xludf.DUMMYFUNCTION("""COMPUTED_VALUE"""),"MEXICO") -> MEXICO | C27: =IFERROR(__xludf.DUMMYFUNCTION("""COMPUTED_VALUE"""),"NORMAL") -> NORMAL | D27: =IFERROR(__xludf.DUMMYFUNCTION("""COMPUTED_VALUE"""),"RAÚL JIMÉNEZ") -> RAÚL JIMÉNEZ | E27: =IFERROR(__xludf.DUMMYFUNCTION("""COMPUTED_VALUE"""),0.0) -> 0 | F27: =IFERROR(__xludf.DUMMYFUNCTION("""COMPUTED_VALUE"""),0.0) -> 0
A28: =IFERROR(__xludf.DUMMYFUNCTION("""COMPUTED_VALUE"""),"MEX18") -> MEX18 | B28: =IFERROR(__xludf.DUMMYFUNCTION("""COMPUTED_VALUE"""),"MEXICO") -> MEXICO | C28: =IFERROR(__xludf.DUMMYFUNCTION("""COMPUTED_VALUE"""),"NORMAL") -> NORMAL | D28: =IFERROR(__xludf.DUMMYFUNCTION("""COMPUTED_VALUE"""),"ALEXIS VEGA") -> ALEXIS VEGA | E28: =IFERROR(__xludf.DUMMYFUNCTION("""COMPUTED_VALUE"""),0.0) -> 0 | F28: =IFERROR(__xludf.DUMMYFUNCTION("""COMPUTED_VALUE"""),0.0) -> 0
A29: =IFERROR(__xludf.DUMMYFUNCTION("""COMPUTED_VALUE"""),"MEX19") -> MEX19 | B29: =IFERROR(__xludf.DUMMYFUNCTION("""COMPUTED_VALUE"""),"MEXICO") -> MEXICO | C29: =IFERROR(__xludf.DUMMYFUNCTION("""COMPUTED_VALUE"""),"NORMAL") -> NORMAL | D29: =IFERROR(__xludf.DUMMYFUNCTION("""COMPUTED_VALUE"""),"ROBERTO ALVARADO") -> ROBERTO ALVARADO | E29: =IFERROR(__xludf.DUMMYFUNCTION("""COMPUTED_VALUE"""),0.0) -> 0 | F29: =IFERROR(__xludf.DUMMYFUNCTION("""COMPUTED_VALUE"""),0.0) -> 0
A30: =IFERROR(__xludf.DUMMYFUNCTION("""COMPUTED_VALUE"""),"MEX20") -> MEX20 | B30: =IFERROR(__xludf.DUMMYFUNCTION("""COMPUTED_VALUE"""),"MEXICO") -> MEXICO | C30: =IFERROR(__xludf.DUMMYFUNCTION("""COMPUTED_VALUE"""),"NORMAL") -> NORMAL | D30: =IFERROR(__xludf.DUMMYFUNCTION("""COMPUTED_VALUE"""),"CÉSAR HUERTA") -> CÉSAR HUERTA | E30: =IFERROR(__xludf.DUMMYFUNCTION("""COMPUTED_VALUE"""),0.0) -> 0 | F30: =IFERROR(__xludf.DUMMYFUNCTION("""COMPUTED_VALUE"""),0.0) -> 0
A31: =IFERROR(__xludf.DUMMYFUNCTION("""COMPUTED_VALUE"""),"RSA01") -> RSA01 | B31: =IFERROR(__xludf.DUMMYFUNCTION("""COMPUTED_VALUE"""),"SOUTHAFRICA") -> SOUTHAFRICA | C31: =IFERROR(__xludf.DUMMYFUNCTION("""COMPUTED_VALUE"""),"BADGE") -> BADGE | D31: =IFERROR(__xludf.DUMMYFUNCTION("""COMPUTED_VALUE"""),"SOUTHAFRICA NATIONAL TEAM") -> SOUTHAFRICA NATIONAL TEAM | E31: =IFERROR(__xludf.DUMMYFUNCTION("""COMPUTED_VALUE"""),0.0) -> 0 | F31: =IFERROR(__xludf.DUMMYFUNCTION("""COMPUTED_VALUE"""),0.0) -> 0
A32: =IFERROR(__xludf.DUMMYFUNCTION("""COMPUTED_VALUE"""),"RSA02") -> RSA02 | B32: =IFERROR(__xludf.DUMMYFUNCTION("""COMPUTED_VALUE"""),"SOUTHAFRICA") -> SOUTHAFRICA | C32: =IFERROR(__xludf.DUMMYFUNCTION("""COMPUTED_VALUE"""),"NORMAL") -> NORMAL | D32: =IFERROR(__xludf.DUMMYFUNCTION("""COMPUTED_VALUE"""),"RONWEN WILLIAMS") -> RONWEN WILLIAMS | E32: =IFERROR(__xludf.DUMMYFUNCTION("""COMPUTED_VALUE"""),0.0) -> 0 | F32: =IFERROR(__xludf.DUMMYFUNCTION("""COMPUTED_VALUE"""),0.0) -> 0
A33: =IFERROR(__xludf.DUMMYFUNCTION("""COMPUTED_VALUE"""),"RSA03") -> RSA03 | B33: =IFERROR(__xludf.DUMMYFUNCTION("""COMPUTED_VALUE"""),"SOUTHAFRICA") -> SOUTHAFRICA | C33: =IFERROR(__xludf.DUMMYFUNCTION("""COMPUTED_VALUE"""),"NORMAL") -> NORMAL | D33: =IFERROR(__xludf.DUMMYFUNCTION("""COMPUTED_VALUE"""),"SIPHO CHAINE") -> SIPHO CHAINE | E33: =IFERROR(__xludf.DUMMYFUNCTION("""COMPUTED_VALUE"""),0.0) -> 0 | F33: =IFERROR(__xludf.DUMMYFUNCTION("""COMPUTED_VALUE"""),0.0) -> 0
A34: =IFERROR(__xludf.DUMMYFUNCTION("""COMPUTED_VALUE"""),"RSA04") -> RSA04 | B34: =IFERROR(__xludf.DUMMYFUNCTION("""COMPUTED_VALUE"""),"SOUTHAFRICA") -> SOUTHAFRICA | C34: =IFERROR(__xludf.DUMMYFUNCTION("""COMPUTED_VALUE"""),"NORMAL") -> NORMAL | D34: =IFERROR(__xludf.DUMMYFUNCTION("""COMPUTED_VALUE"""),"AUBREY MODIBA") -> AUBREY MODIBA | E34: =IFERROR(__xludf.DUMMYFUNCTION("""COMPUTED_VALUE"""),0.0) -> 0 | F34: =IFERROR(__xludf.DUMMYFUNCTION("""COMPUTED_VALUE"""),0.0) -> 0
A35: =IFERROR(__xludf.DUMMYFUNCTION("""COMPUTED_VALUE"""),"RSA05") -> RSA05 | B35: =IFERROR(__xludf.DUMMYFUNCTION("""COMPUTED_VALUE"""),"SOUTHAFRICA") -> SOUTHAFRICA | C35: =IFERROR(__xludf.DUMMYFUNCTION("""COMPUTED_VALUE"""),"NORMAL") -> NORMAL | D35: =IFERROR(__xludf.DUMMYFUNCTION("""COMPUTED_VALUE"""),"SAMUKELE KABINI") -> SAMUKELE KABINI | E35: =IFERROR(__xludf.DUMMYFUNCTION("""COMPUTED_VALUE"""),0.0) -> 0 | F35: =IFERROR(__xludf.DUMMYFUNCTION("""COMPUTED_VALUE"""),0.0) -> 0
A36: =IFERROR(__xludf.DUMMYFUNCTION("""COMPUTED_VALUE"""),"RSA06") -> RSA06 | B36: =IFERROR(__xludf.DUMMYFUNCTION("""COMPUTED_VALUE"""),"SOUTHAFRICA") -> SOUTHAFRICA | C36: =IFERROR(__xludf.DUMMYFUNCTION("""COMPUTED_VALUE"""),"NORMAL") -> NORMAL | D36: =IFERROR(__xludf.DUMMYFUNCTION("""COMPUTED_VALUE"""),"MBEKEZLI MBOKAZI") -> MBEKEZLI MBOKAZI | E36: =IFERROR(__xludf.DUMMYFUNCTION("""COMPUTED_VALUE"""),0.0) -> 0 | F36: =IFERROR(__xludf.DUMMYFUNCTION("""COMPUTED_VALUE"""),0.0) -> 0
A37: =IFERROR(__xludf.DUMMYFUNCTION("""COMPUTED_VALUE"""),"RSA07") -> RSA07 | B37: =IFERROR(__xludf.DUMMYFUNCTION("""COMPUTED_VALUE"""),"SOUTHAFRICA") -> SOUTHAFRICA | C37: =IFERROR(__xludf.DUMMYFUNCTION("""COMPUTED_VALUE"""),"NORMAL") -> NORMAL | D37: =IFERROR(__xludf.DUMMYFUNCTION("""COMPUTED_VALUE"""),"KHULUMANI NDAMANE") -> KHULUMANI NDAMANE | E37: =IFERROR(__xludf.DUMMYFUNCTION("""COMPUTED_VALUE"""),0.0) -> 0 | F37: =IFERROR(__xludf.DUMMYFUNCTION("""COMPUTED_VALUE"""),0.0) -> 0
A38: =IFERROR(__xludf.DUMMYFUNCTION("""COMPUTED_VALUE"""),"RSA08") -> RSA08 | B38: =IFERROR(__xludf.DUMMYFUNCTION("""COMPUTED_VALUE"""),"SOUTHAFRICA") -> SOUTHAFRICA | C38: =IFERROR(__xludf.DUMMYFUNCTION("""COMPUTED_VALUE"""),"NORMAL") -> NORMAL | D38: =IFERROR(__xludf.DUMMYFUNCTION("""COMPUTED_VALUE"""),"SIVABONGA NGEZANA") -> SIVABONGA NGEZANA | E38: =IFERROR(__xludf.DUMMYFUNCTION("""COMPUTED_VALUE"""),0.0) -> 0 | F38: =IFERROR(__xludf.DUMMYFUNCTION("""COMPUTED_VALUE"""),0.0) -> 0
A39: =IFERROR(__xludf.DUMMYFUNCTION("""COMPUTED_VALUE"""),"RSA09") -> RSA09 | B39: =IFERROR(__xludf.DUMMYFUNCTION("""COMPUTED_VALUE"""),"SOUTHAFRICA") -> SOUTHAFRICA | C39: =IFERROR(__xludf.DUMMYFUNCTION("""COMPUTED_VALUE"""),"NORMAL") -> NORMAL | D39: =IFERROR(__xludf.DUMMYFUNCTION("""COMPUTED_VALUE"""),"KHULISO MUDAU") -> KHULISO MUDAU | E39: =IFERROR(__xludf.DUMMYFUNCTION("""COMPUTED_VALUE"""),0.0) -> 0 | F39: =IFERROR(__xludf.DUMMYFUNCTION("""COMPUTED_VALUE"""),0.0) -> 0
A40: =IFERROR(__xludf.DUMMYFUNCTION("""COMPUTED_VALUE"""),"RSA10") -> RSA10 | B40: =IFERROR(__xludf.DUMMYFUNCTION("""COMPUTED_VALUE"""),"SOUTHAFRICA") -> SOUTHAFRICA | C40: =IFERROR(__xludf.DUMMYFUNCTION("""COMPUTED_VALUE"""),"NORMAL") -> NORMAL | D40: =IFERROR(__xludf.DUMMYFUNCTION("""COMPUTED_VALUE"""),"NKOSINATHI SIBISI") -> NKOSINATHI SIBISI | E40: =IFERROR(__xludf.DUMMYFUNCTION("""COMPUTED_VALUE"""),0.0) -> 0 | F40: =IFERROR(__xludf.DUMMYFUNCTION("""COMPUTED_VALUE"""),0.0) -> 0
...

Sheet 01_PANINI
A1: ID | B1: SECTION | C1: TYPE | D1: DESCRIPTION | E1: QUANTITY | F1: OWNED
A2: 00 | B2: SECTION 1 | C2: SPECIAL | D2: WE ARE PANINI | E2: 0 | F2: 0
A3: FWC1 | B3: SECTION 1 | C3: SPECIAL | D3: FWC 1 | E3: 0 | F3: 0
A4: FWC2 | B4: SECTION 1 | C4: SPECIAL | D4: FWC 2 | E4: 0 | F4: 0
A5: FWC3 | B5: SECTION 1 | C5: SPECIAL | D5: FWC 3 | E5: 0 | F5: 0
A6: FWC4 | B6: SECTION 1 | C6: SPECIAL | D6: FWC 4 | E6: 0 | F6: 0
A7: FWC5 | B7: SECTION 1 | C7: SPECIAL | D7: FWC 5 | E7: 0 | F7: 0
A8: FWC6 | B8: SECTION 1 | C8: SPECIAL | D8: FWC 6 | E8: 0 | F8: 0
A9: FWC7 | B9: SECTION 1 | C9: SPECIAL | D9: FWC 7 | E9: 0 | F9: 0
A10: FWC8 | B10: SECTION 1 | C10: SPECIAL | D10: FWC 8 | E10: 0 | F10: 0

Sheet 02_GRUPO_A
A1: ID | B1: TEAM | C1: TYPE | D1: PLAYER | E1: QUANTITY | F1: OWNED
A2: MEX01 | B2: MEXICO | C2: BADGE | D2: MEXICO NATIONAL TEAM | E2: 0 | F2: 0
A3: MEX02 | B3: MEXICO | C3: NORMAL | D3: LUIS MALAGÓN | E3: 0 | F3: 0
A4: MEX03 | B4: MEXICO | C4: NORMAL | D4: JOHAN VÁSQUEZ | E4: 0 | F4: 0
A5: MEX04 | B5: MEXICO | C5: NORMAL | D5: JORGE SÁNCHEZ | E5: 0 | F5: 0
A6: MEX05 | B6: MEXICO | C6: NORMAL | D6: CÉSAR MONTES | E6: 0 | F6: 0
A7: MEX06 | B7: MEXICO | C7: NORMAL | D7: JESÚS GALLARDO | E7: 0 | F7: 0
A8: MEX07 | B8: MEXICO | C8: NORMAL | D8: ISRAEL REYES | E8: 0 | F8: 0
A9: MEX08 | B9: MEXICO | C9: NORMAL | D9: DIEGO LAINEZ | E9: 0 | F9: 0
A10: MEX09 | B10: MEXICO | C10: NORMAL | D10: CARLOS RODRÍGUEZ | E10: 0 | F10: 0
A11: MEX10 | B11: MEXICO | C11: NORMAL | D11: EDSON ÁLVAREZ | E11: 0 | F11: 0
A12: MEX11 | B12: MEXICO | C12: NORMAL | D12: ORBELÍN PINEDA | E12: 0 | F12: 0
A13: MEX12 | B13: MEXICO | C13: NORMAL | D13: MARCEL RUÍZ | E13: 0 | F13: 0
... A81: CZE20 | B81: CZCECHIA | C81: NORMAL | D81: PATRICK SHICK | E81: 0 | F81: 0

Sheet 03_GRUPO_B
A1: ID | B1: TEAM | C1: TYPE | D1: PLAYER | E1: QUANTITY | F1: OWNED
A2: CAN01 | B2: CANADA | C2: BADGE | D2: CANADA NATIONAL TEAM | E2: 0 | F2: 0
A3: CAN02 | B3: CANADA | C3: NORMAL | D3: DAYNE ST. CLAIR | E3: 0 | F3: 0
A4: CAN03 | B4: CANADA | C4: NORMAL | D4: ALPHONSO DAVIES | E4: 0 | F4: 0
A5: CAN04 | B5: CANADA | C5: NORMAL | D5: ALISTAIR JOHNSTON | E5: 0 | F5: 0
A6: CAN05 | B6: CANADA | C6: NORMAL | D6: SAMUEL ADEKUGBE | E6: 0 | F6: 0
A7: CAN06 | B7: CANADA | C7: NORMAL | D7: RICHIE LARVEA | E7: 0 | F7: 0
A8: CAN07 | B8: CANADA | C8: NORMAL | D8: DEREK CORNELIUS | E8: 0 | F8: 0
A9: CAN08 | B9: CANADA | C9: NORMAL | D9: MOISE BOMBITO | E9: 0 | F9: 0
A10: CAN09 | B10: CANADA | C10: NORMAL | D10: KAMAL MILLER | E10: 0 | F10: 0
A11: CAN10 | B11: CANADA | C11: NORMAL | D11: STEPHEN EUSTAQUIO | E11: 0 | F11: 0
A12: CAN11 | B12: CANADA | C12: NORMAL | D12: ISMAEL KONE | E12: 0 | F12: 0
A13: CAN12 | B13: CANADA | C13: NORMAL | D13: JONATHAN OSORIO | E13: 0 | F13: 0
... A81: SUI20 | B81: SWITZERLAND | C81: NORMAL | D81: ZEKI AMDOUNI | E81: 0 | F81: 0

Sheet 04_GRUPO_C
A1: ID | B1: TEAM | C1: TYPE | D1: PLAYER | E1: QUANTITY | F1: OWNED
A2: BRA01 | B2: BRAZIL | C2: BADGE | D2: BRAZIL NATIONAL TEAM | E2: 0 | F2: 0
A3: BRA02 | B3: BRAZIL | C3: NORMAL | D3: ALISSON | E3: 0 | F3: 0
A4: BRA03 | B4: BRAZIL | C4: NORMAL | D4: BENTO | E4: 0 | F4: 0
A5: BRA04 | B5: BRAZIL | C5: NORMAL | D5: MARQUINOS | E5: 0 | F5: 0
A6: BRA05 | B6: BRAZIL | C6: NORMAL | D6: EDER MILITAO | E6: 0 | F6: 0
A7: BRA06 | B7: BRAZIL | C7: NORMAL | D7: GABRIEL MAGALHAES | E7: 0 | F7: 0
A8: BRA07 | B8: BRAZIL | C8: NORMAL | D8: DANILO | E8: 0 | F8: 0
A9: BRA08 | B9: BRAZIL | C9: NORMAL | D9: WESLEY | E9: 0 | F9: 0
A10: BRA09 | B10: BRAZIL | C10: NORMAL | D10: LUCAS PAQUETÁ | E10: 0 | F10: 0
A11: BRA10 | B11: BRAZIL | C11: NORMAL | D11: CASEMIRO | E11: 0 | F11: 0
A12: BRA11 | B12: BRAZIL | C12: NORMAL | D12: BRUNO GUIMARAES | E12: 0 | F12: 0
A13: BRA12 | B13: BRAZIL | C13: NORMAL | D13: LUIZ HENRIQUE | E13: 0 | F13: 0
... A81: SCO20 | B81: SCOTLAND | C81: NORMAL | D81: BEN GANNON-DOAK | E81: 0 | F81: 0

Sheet 05_GRUPO_D
A1: ID | B1: TEAM | C1: TYPE | D1: PLAYER | E1: QUANTITY | F1: OWNED
A2: USA01 | B2: UNITED STATES | C2: BADGE | D2: UNITED STATES NATIONAL TEAM | E2: 0 | F2: 0
A3: USA02 | B3: UNITED STATES | C3: NORMAL | D3: MATT FREESE | E3: 0 | F3: 0
A4: USA03 | B4: UNITED STATES | C4: NORMAL | D4: CHRIS RICHARDS | E4: 0 | F4: 0
A5: USA04 | B5: UNITED STATES | C5: NORMAL | D5: TIM REAM | E5: 0 | F5: 0
A6: USA05 | B6: UNITED STATES | C6: NORMAL | D6: MARK MCKENZIE | E6: 0 | F6: 0
A7: USA06 | B7: UNITED STATES | C7: NORMAL | D7: ALEX FREEMAN | E7: 0 | F7: 0
A8: USA07 | B8: UNITED STATES | C8: NORMAL | D8: ANTONEE ROBINSON | E8: 0 | F8: 0
A9: USA08 | B9: UNITED STATES | C9: NORMAL | D9: TYLER ADAMS | E9: 0 | F9: 0
A10: USA09 | B10: UNITED STATES | C10: NORMAL | D10: TANNER TESSMANN | E10: 0 | F10: 0
A11: USA10 | B11: UNITED STATES | C11: NORMAL | D11: WESTON MCKENNIE | E11: 0 | F11: 0
A12: USA11 | B12: UNITED STATES | C12: NORMAL | D12: CRISTIAN ROLDAN | E12: 0 | F12: 0
A13: USA12 | B13: UNITED STATES | C13: NORMAL | D13: TIMOTHY WEAH | E13: 0 | F13: 0
... A81: TUR20 | B81: TURKEY | C81: NORMAL | D81: KENAN YILDIZ | E81: 0 | F81: 0

Sheet 06_GRUPO_E
A1: ID | B1: TEAM | C1: TYPE | D1: PLAYER | E1: QUANTITY | F1: OWNED
A2: GER01 | B2: GERMANY | C2: BADGE | D2: GERMANY NATIONAL TEAM | E2: 0 | F2: 0
A3: GER02 | B3: GERMANY | C3: NORMAL | D3: MARC-ANDRE TER STEGEN | E3: 0 | F3: 0
A4: GER03 | B4: GERMANY | C4: NORMAL | D4: JONATHAN TAH | E4: 0 | F4: 0
A5: GER04 | B5: GERMANY | C5: NORMAL | D5: DAIVD RAUM | E5: 0 | F5: 0
A6: GER05 | B6: GERMANY | C6: NORMAL | D6: NICO SCHLOTTERBECK | E6: 0 | F6: 0
A7: GER06 | B7: GERMANY | C7: NORMAL | D7: ANTONIO RUDIGER | E7: 0 | F7: 0
A8: GER07 | B8: GERMANY | C8: NORMAL | D8: WALDEMAR ANTON | E8: 0 | F8: 0
A9: GER08 | B9: GERMANY | C9: NORMAL | D9: RIDLE BAKU | E9: 0 | F9: 0
A10: GER09 | B10: GERMANY | C10: NORMAL | D10: MAXIMILIAN MITTELSTADT | E10: 0 | F10: 0
A11: GER10 | B11: GERMANY | C11: NORMAL | D11: JOSHUA KIMMICH | E11: 0 | F11: 0
A12: GER11 | B12: GERMANY | C12: NORMAL | D12: FLORIAN WIRTZ | E12: 0 | F12: 0
A13: GER12 | B13: GERMANY | C13: NORMAL | D13: FELIZ NMECHA | E13: 0 | F13: 0
... A81: ECU20 | B81: ECUADOR | C81: NORMAL | D81: ENNER VALENCIA | E81: 0 | F81: 0

Sheet 07_GRUPO_F
A1: ID | B1: TEAM | C1: TYPE | D1: PLAYER | E1: QUANTITY | F1: OWNED
A2: NED01 | B2: NETHERLANDS | C2: BADGE | D2: NETHERLANDS NATIONAL TEAM | E2: 0 | F2: 0
A3: NED02 | B3: NETHERLANDS | C3: NORMAL | D3: BART VERBRUGGEN | E3: 0 | F3: 0
A4: NED03 | B4: NETHERLANDS | C4: NORMAL | D4: VIRGIL VAN DIJK | E4: 0 | F4: 0
A5: NED04 | B5: NETHERLANDS | C5: NORMAL | D5: MICKY VAN DE VEN | E5: 0 | F5: 0
A6: NED05 | B6: NETHERLANDS | C6: NORMAL | D6: JURRIEN TIMBER | E6: 0 | F6: 0
A7: NED06 | B7: NETHERLANDS | C7: NORMAL | D7: DENZEL DUMFRIES | E7: 0 | F7: 0
A8: NED07 | B8: NETHERLANDS | C8: NORMAL | D8: NATHAN AKE | E8: 0 | F8: 0
A9: NED08 | B9: NETHERLANDS | C9: NORMAL | D9: JAREMIE FRIMPONG | E9: 0 | F9: 0
A10: NED09 | B10: NETHERLANDS | C10: NORMAL | D10: JAN PAUL VAN HECKE | E10: 0 | F10: 0
A11: NED10 | B11: NETHERLANDS | C11: NORMAL | D11: TIJJANI REIJNDERS | E11: 0 | F11: 0
A12: NED11 | B12: NETHERLANDS | C12: NORMAL | D12: RYAN GRAVENBERCH | E12: 0 | F12: 0
A13: NED12 | B13: NETHERLANDS | C13: NORMAL | D13: TEUN KOOPMEINERS | E13: 0 | F13: 0
... A81: TUN20 | B81: TUNISIA | C81: NORMAL | D81: NAIM SLITTI | E81: 0 | F81: 0

Sheet 08_STICKERS_COCA_COLA
A1: ID | B1: SECTION | C1: TYPE | D1: DESCRIPTION | E1: QUANTITY | F1: OWNED
A2: CC1 | B2: SECTION 3 | C2: SPECIAL | D2: LAMINE YAMAL | E2: 0 | F2: 0
A3: CC2 | B3: SECTION 3 | C3: SPECIAL | D3: JOSHUE KIMMICH | E3: 0 | F3: 0
A4: CC3 | B4: SECTION 3 | C4: SPECIAL | D4: HARRY KANE | E4: 0 | F4: 0
A5: CC4 | B5: SECTION 3 | C5: SPECIAL | D5: SANTIAGO GIMENEZ | E5: 0 | F5: 0
A6: CC5 | B6: SECTION 3 | C6: SPECIAL | D6: JOSKO GVARDIOL | E6: 0 | F6: 0
A7: CC6 | B7: SECTION 3 | C7: SPECIAL | D7: FEDERICO VALVERDE | E7: 0 | F7: 0
A8: CC7 | B8: SECTION 3 | C8: SPECIAL | D8: JEFFERSON LERMA | E8: 0 | F8: 0
A9: CC8 | B9: SECTION 3 | C9: SPECIAL | D9: ENNER VALENCIA | E9: 0 | F9: 0
A10: CC9 | B10: SECTION 3 | C10: SPECIAL | D10: GABRIEL MAGALHAES | E10: 0 | F10: 0
A11: CC10 | B11: SECTION 3 | C11: SPECIAL | D11: VIRGIL VAN DIJK | E11: 0 | F11: 0
A12: CC11 | B12: SECTION 3 | C12: SPECIAL | D12: ALPHONSO DAVIES | E12: 0 | F12: 0
A13: CC12 | B13: SECTION 3 | C13: SPECIAL | D13: EMILIANO MARTINEZ | E13: 0 | F13: 0
... A15: CC14 | B15: SECTION 3 | C15: SPECIAL | D15: LAUTARO MARTINEZ | E15: 0 | F15: 0

Sheet 09_GRUPO_G
A1: ID | B1: TEAM | C1: TYPE | D1: PLAYER | E1: QUANTITY | F1: OWNED
A2: BEL01 | B2: BELGIUM | C2: BADGE | D2: BELGIUM NATIONAL TEAM | E2: 0 | F2: 0
A3: BEL02 | B3: BELGIUM | C3: NORMAL | D3: THIBAUT COURTOIS | E3: 0 | F3: 0
A4: BEL03 | B4: BELGIUM | C4: NORMAL | D4: ARTHUR THEATE | E4: 0 | F4: 0
A5: BEL04 | B5: BELGIUM | C5: NORMAL | D5: TIMOTHY CASTAGNE | E5: 0 | F5: 0
A6: BEL05 | B6: BELGIUM | C6: NORMAL | D6: ZENO DEBASR | E6: 0 | F6: 0
A7: BEL06 | B7: BELGIUM | C7: NORMAL | D7: BRANDON MECHELE | E7: 0 | F7: 0
A8: BEL07 | B8: BELGIUM | C8: NORMAL | D8: MAXIM DE CUYPER | E8: 0 | F8: 0
A9: BEL08 | B9: BELGIUM | C9: NORMAL | D9: THOMAS MEUNIER | E9: 0 | F9: 0
A10: BEL09 | B10: BELGIUM | C10: NORMAL | D10: YOURI TIELEMANS | E10: 0 | F10: 0
A11: BEL10 | B11: BELGIUM | C11: NORMAL | D11: AMADOU ONANA | E11: 0 | F11: 0
A12: BEL11 | B12: BELGIUM | C12: NORMAL | D12: NICOLAS RASKIN | E12: 0 | F12: 0
A13: BEL12 | B13: BELGIUM | C13: NORMAL | D13: ALEXIS SAELEMAEKERS | E13: 0 | F13: 0
... A81: NZL20 | B81: NEW ZEALAND | C81: NORMAL | D81: KOSTA BARBAROUSES | E81: 0 | F81: 0

Sheet 10_GRUPO_H
A1: ID | B1: TEAM | C1: TYPE | D1: PLAYER | E1: QUANTITY | F1: OWNED
A2: ESP01 | B2: SPAIN | C2: BADGE | D2: SPAIN NATIONAL TEAM | E2: 0 | F2: 0
A3: ESP02 | B3: SPAIN | C3: NORMAL | D3: UNAI SIMON | E3: 0 | F3: 0
A4: ESP03 | B4: SPAIN | C4: NORMAL | D4: ROBIN LE NORMAND | E4: 0 | F4: 0
A5: ESP04 | B5: SPAIN | C5: NORMAL | D5: AYMERIC LAPORTE | E5: 0 | F5: 0
A6: ESP05 | B6: SPAIN | C6: NORMAL | D6: DEAN HUIJSEN | E6: 0 | F6: 0
A7: ESP06 | B7: SPAIN | C7: NORMAL | D7: PEDRO PORRO | E7: 0 | F7: 0
A8: ESP07 | B8: SPAIN | C8: NORMAL | D8: DANI CARVAJAL | E8: 0 | F8: 0
A9: ESP08 | B9: SPAIN | C9: NORMAL | D9: MARC CUCURELLA | E9: 0 | F9: 0
A10: ESP09 | B10: SPAIN | C10: NORMAL | D10: MARTIN ZUBIMENDI | E10: 0 | F10: 0
A11: ESP10 | B11: SPAIN | C11: NORMAL | D11: RODRI | E11: 0 | F11: 0
A12: ESP11 | B12: SPAIN | C12: NORMAL | D12: PEDRI | E12: 0 | F12: 0
A13: ESP12 | B13: SPAIN | C13: NORMAL | D13: FABIAN RUIZ | E13: 0 | F13: 0
... A81: URU20 | B81: URUGUAY | C81: NORMAL | D81: FACUNDO PELLISTRI | E81: 0 | F81: 0

Sheet 11_GRUPO_I
A1: ID | B1: TEAM | C1: TYPE | D1: PLAYER | E1: QUANTITY | F1: OWNED
A2: FRA01 | B2: FRANCE | C2: BADGE | D2: FRANCE NATIONAL TEAM | E2: 0 | F2: 0
A3: FRA02 | B3: FRANCE | C3: NORMAL | D3: MIKE MAIGNAN | E3: 0 | F3: 0
A4: FRA03 | B4: FRANCE | C4: NORMAL | D4: THEO HERNANDEZ | E4: 0 | F4: 0
A5: FRA04 | B5: FRANCE | C5: NORMAL | D5: WILLIAM SALIBA | E5: 0 | F5: 0
A6: FRA05 | B6: FRANCE | C6: NORMAL | D6: JULES KOUNDE | E6: 0 | F6: 0
A7: FRA06 | B7: FRANCE | C7: NORMAL | D7: IBRAHIMA KONATE | E7: 0 | F7: 0
A8: FRA07 | B8: FRANCE | C8: NORMAL | D8: DAYOT UPAMECANO | E8: 0 | F8: 0
A9: FRA08 | B9: FRANCE | C9: NORMAL | D9: LUCAS DIGNE | E9: 0 | F9: 0
A10: FRA09 | B10: FRANCE | C10: NORMAL | D10: AURELIEN TCHOUAMENI | E10: 0 | F10: 0
A11: FRA10 | B11: FRANCE | C11: NORMAL | D11: EDUARDO CAMAVINGA | E11: 0 | F11: 0
A12: FRA11 | B12: FRANCE | C12: NORMAL | D12: MANU KONE | E12: 0 | F12: 0
A13: FRA12 | B13: FRANCE | C13: NORMAL | D13: ADRIEN RABIOT | E13: 0 | F13: 0
... A81: NOR20 | B81: NORWAY | C81: NORMAL | D81: OSCAR BOBB | E81: 0 | F81: 0

Sheet 12_GRUPO_J
A1: ID | B1: TEAM | C1: TYPE | D1: PLAYER | E1: QUANTITY | F1: OWNED
A2: ARG01 | B2: ARGENTINA | C2: BADGE | D2: ARGENTINA NATIONAL TEAM | E2: 0 | F2: 0
A3: ARG02 | B3: ARGENTINA | C3: NORMAL | D3: EMILIANO MARTINEZ | E3: 0 | F3: 0
A4: ARG03 | B4: ARGENTINA | C4: NORMAL | D4: NAHUEL MOLINA | E4: 0 | F4: 0
A5: ARG04 | B5: ARGENTINA | C5: NORMAL | D5: CRISTIAN ROMERO | E5: 0 | F5: 0
A6: ARG05 | B6: ARGENTINA | C6: NORMAL | D6: NICOLAS OTAMENDI | E6: 0 | F6: 0
A7: ARG06 | B7: ARGENTINA | C7: NORMAL | D7: NICOLAS TAGLIAFICO | E7: 0 | F7: 0
A8: ARG07 | B8: ARGENTINA | C8: NORMAL | D8: LEONARDO BALERDI | E8: 0 | F8: 0
A9: ARG08 | B9: ARGENTINA | C9: NORMAL | D9: ENZO FERNANDEZ | E9: 0 | F9: 0
A10: ARG09 | B10: ARGENTINA | C10: NORMAL | D10: ALEXIS MAC ALLISTER | E10: 0 | F10: 0
A11: ARG10 | B11: ARGENTINA | C11: NORMAL | D11: RODRIGO DE PAUL | E11: 0 | F11: 0
A12: ARG11 | B12: ARGENTINA | C12: NORMAL | D12: EXEQUIEL PALACIOS | E12: 0 | F12: 0
A13: ARG12 | B13: ARGENTINA | C13: NORMAL | D13: LEANDRO PAREDES | E13: 0 | F13: 0
... A81: JOR20 | B81: JORDAN | C81: NORMAL | D81: IBRAHIM SABRA | E81: 0 | F81: 0

Sheet 13_GRUPO_K
A1: ID | B1: TEAM | C1: TYPE | D1: PLAYER | E1: QUANTITY | F1: OWNED
A2: POR 01 | B2: PORTUGAL | C2: BADGE | D2: PORTUGAL NATIONAL TEAM | E2: 0 | F2: 0
A3: POR 02 | B3: PORTUGAL | C3: NORMAL | D3: DIOGO COSTA | E3: 0 | F3: 0
A4: POR 03 | B4: PORTUGAL | C4: NORMAL | D4: JOSE SA | E4: 0 | F4: 0
A5: POR 04 | B5: PORTUGAL | C5: NORMAL | D5: RUBEN DIAS | E5: 0 | F5: 0
A6: POR 05 | B6: PORTUGAL | C6: NORMAL | D6: JOAO CANCELO | E6: 0 | F6: 0
A7: POR 06 | B7: PORTUGAL | C7: NORMAL | D7: DIOGO DALOT | E7: 0 | F7: 0
A8: POR 07 | B8: PORTUGAL | C8: NORMAL | D8: NUNO MENDES | E8: 0 | F8: 0
A9: POR 08 | B9: PORTUGAL | C9: NORMAL | D9: GONCALO INACIO | E9: 0 | F9: 0
A10: POR 09 | B10: PORTUGAL | C10: NORMAL | D10: BERNARDO SILVA | E10: 0 | F10: 0
A11: POR 10 | B11: PORTUGAL | C11: NORMAL | D11: BRUNO FERNANDES | E11: 0 | F11: 0
A12: POR 11 | B12: PORTUGAL | C12: NORMAL | D12: RUBEN NEVES | E12: 0 | F12: 0
A13: POR 12 | B13: PORTUGAL | C13: NORMAL | D13: VITINHA | E13: 0 | F13: 0
... A81: COL20 | B81: COLOMBIA | C81: NORMAL | D81: LUIS DIAZ | E81: 0 | F81: 0

Sheet 14_GRUPO_L
A1: ID | B1: TEAM | C1: TYPE | D1: PLAYER | E1: QUANTITY | F1: OWNED
A2: ENG 01 | B2: ENGLAND | C2: BADGE | D2: ENGLAND NATIONAL TEAM | E2: 0 | F2: 0
A3: ENG 02 | B3: ENGLAND | C3: NORMAL | D3: JORDAN PICKFORD | E3: 0 | F3: 0
A4: ENG 03 | B4: ENGLAND | C4: NORMAL | D4: JOHN STONES | E4: 0 | F4: 0
A5: ENG 04 | B5: ENGLAND | C5: NORMAL | D5: MARC GUEHI | E5: 0 | F5: 0
A6: ENG 05 | B6: ENGLAND | C6: NORMAL | D6: EZRI KONSA | E6: 0 | F6: 0
A7: ENG 06 | B7: ENGLAND | C7: NORMAL | D7: TRENT ALEXANDER-ARNOLD | E7: 0 | F7: 0
A8: ENG 07 | B8: ENGLAND | C8: NORMAL | D8: REECE JAMES | E8: 0 | F8: 0
A9: ENG 08 | B9: ENGLAND | C9: NORMAL | D9: DAN BURN | E9: 0 | F9: 0
A10: ENG 09 | B10: ENGLAND | C10: NORMAL | D10: JORDAN HENDERSON | E10: 0 | F10: 0
A11: ENG 10 | B11: ENGLAND | C11: NORMAL | D11: DECLAN RICE | E11: 0 | F11: 0
A12: ENG 11 | B12: ENGLAND | C12: NORMAL | D12: JUDE BELLINGHAM | E12: 0 | F12: 0
A13: ENG 12 | B13: ENGLAND | C13: NORMAL | D13: COLE PALMER | E13: 0 | F13: 0
... A81: PAN20 | B81: PANAMA | C81: NORMAL | D81: ALBERTO QUINTERO | E81: 0 | F81: 0

Sheet 15_FIFA_WORLD_CUP_CHAMPIONS
A1: ID | B1: SECTION | C1: TYPE | D1: DESCRIPTION | E1: QUANTITY | F1: OWNED
A2: ITALIA 1934 FWC9 | B2: SECTION 4 | C2: SPECIAL | D2: FWC9 | E2: 0 | F2: 0
A3: BRAZIL 1950 FWC10 | B3: SECTION 4 | C3: SPECIAL | D3: FWC10 | E3: 0 | F3: 0
A4: SWITZERLAND 1954 FWC11 | B4: SECTION 4 | C4: SPECIAL | D4: FWC11 | E4: 0 | F4: 0
A5: CHILE 1962 FWC12 | B5: SECTION 4 | C5: SPECIAL | D5: FWC12 | E5: 0 | F5: 0
A6: GERMANY 1974 FWC13 | B6: SECTION 4 | C6: SPECIAL | D6: FWC13 | E6: 0 | F6: 0
A7: MEXICO 1986 FWC14 | B7: SECTION 4 | C7: SPECIAL | D7: FWC14 | E7: 0 | F7: 0
A8: UNITED STATES 1994 FWC15 | B8: SECTION 4 | C8: SPECIAL | D8: FWC15 | E8: 0 | F8: 0
A9: SOUTH KOREA/JAPAN 2002 FWC16 | B9: SECTION 4 | C9: SPECIAL | D9: FWC16 | E9: 0 | F9: 0
A10: GERMANY 2006 FWC17 | B10: SECTION 4 | C10: SPECIAL | D10: FWC17 | E10: 0 | F10: 0
A11: BRAZIL 2014 FWC18 | B11: SECTION 4 | C11: SPECIAL | D11: FWC18 | E11: 0 | F11: 0
A12: QATAR 2022 FWC19 | B12: SECTION 4 | C12: SPECIAL | D12: FWC19 | E12: 0 | F12: 0

Sheet MISSING
A1: ID | B1: SECTION | C1: TYPE | D1: PLAYER | E1: QUANTITY
A2: =IFERROR(__xludf.DUMMYFUNCTION("FILTER(MASTER!A2:E1000, MASTER!E2:E1000=0)"),"00") -> 00 | B2: =IFERROR(__xludf.DUMMYFUNCTION("""COMPUTED_VALUE"""),"SECTION 1") -> SECTION 1 | C2: =IFERROR(__xludf.DUMMYFUNCTION("""COMPUTED_VALUE"""),"SPECIAL") -> SPECIAL | D2: =IFERROR(__xludf.DUMMYFUNCTION("""COMPUTED_VALUE"""),"WE ARE PANINI") -> WE ARE PANINI | E2: =IFERROR(__xludf.DUMMYFUNCTION("""COMPUTED_VALUE"""),0.0) -> 0
A3: =IFERROR(__xludf.DUMMYFUNCTION("""COMPUTED_VALUE"""),"FWC1") -> FWC1 | B3: =IFERROR(__xludf.DUMMYFUNCTION("""COMPUTED_VALUE"""),"SECTION 1") -> SECTION 1 | C3: =IFERROR(__xludf.DUMMYFUNCTION("""COMPUTED_VALUE"""),"SPECIAL") -> SPECIAL | D3: =IFERROR(__xludf.DUMMYFUNCTION("""COMPUTED_VALUE"""),"FWC 1") -> FWC 1 | E3: =IFERROR(__xludf.DUMMYFUNCTION("""COMPUTED_VALUE"""),0.0) -> 0
A4: =IFERROR(__xludf.DUMMYFUNCTION("""COMPUTED_VALUE"""),"FWC2") -> FWC2 | B4: =IFERROR(__xludf.DUMMYFUNCTION("""COMPUTED_VALUE"""),"SECTION 1") -> SECTION 1 | C4: =IFERROR(__xludf.DUMMYFUNCTION("""COMPUTED_VALUE"""),"SPECIAL") -> SPECIAL | D4: =IFERROR(__xludf.DUMMYFUNCTION("""COMPUTED_VALUE"""),"FWC 2") -> FWC 2 | E4: =IFERROR(__xludf.DUMMYFUNCTION("""COMPUTED_VALUE"""),0.0) -> 0
A5: =IFERROR(__xludf.DUMMYFUNCTION("""COMPUTED_VALUE"""),"FWC3") -> FWC3 | B5: =IFERROR(__xludf.DUMMYFUNCTION("""COMPUTED_VALUE"""),"SECTION 1") -> SECTION 1 | C5: =IFERROR(__xludf.DUMMYFUNCTION("""COMPUTED_VALUE"""),"SPECIAL") -> SPECIAL | D5: =IFERROR(__xludf.DUMMYFUNCTION("""COMPUTED_VALUE"""),"FWC 3") -> FWC 3 | E5: =IFERROR(__xludf.DUMMYFUNCTION("""COMPUTED_VALUE"""),0.0) -> 0
A6: =IFERROR(__xludf.DUMMYFUNCTION("""COMPUTED_VALUE"""),"FWC4") -> FWC4 | B6: =IFERROR(__xludf.DUMMYFUNCTION("""COMPUTED_VALUE"""),"SECTION 1") -> SECTION 1 | C6: =IFERROR(__xludf.DUMMYFUNCTION("""COMPUTED_VALUE"""),"SPECIAL") -> SPECIAL | D6: =IFERROR(__xludf.DUMMYFUNCTION("""COMPUTED_VALUE"""),"FWC 4") -> FWC 4 | E6: =IFERROR(__xludf.DUMMYFUNCTION("""COMPUTED_VALUE"""),0.0) -> 0
A7: =IFERROR(__xludf.DUMMYFUNCTION("""COMPUTED_VALUE"""),"FWC5") -> FWC5 | B7: =IFERROR(__xludf.DUMMYFUNCTION("""COMPUTED_VALUE"""),"SECTION 1") -> SECTION 1 | C7: =IFERROR(__xludf.DUMMYFUNCTION("""COMPUTED_VALUE"""),"SPECIAL") -> SPECIAL | D7: =IFERROR(__xludf.DUMMYFUNCTION("""COMPUTED_VALUE"""),"FWC 5") -> FWC 5 | E7: =IFERROR(__xludf.DUMMYFUNCTION("""COMPUTED_VALUE"""),0.0) -> 0
A8: =IFERROR(__xludf.DUMMYFUNCTION("""COMPUTED_VALUE"""),"FWC6") -> FWC6 | B8: =IFERROR(__xludf.DUMMYFUNCTION("""COMPUTED_VALUE"""),"SECTION 1") -> SECTION 1 | C8: =IFERROR(__xludf.DUMMYFUNCTION("""COMPUTED_VALUE"""),"SPECIAL") -> SPECIAL | D8: =IFERROR(__xludf.DUMMYFUNCTION("""COMPUTED_VALUE"""),"FWC 6") -> FWC 6 | E8: =IFERROR(__xludf.DUMMYFUNCTION("""COMPUTED_VALUE"""),0.0) -> 0
A9: =IFERROR(__xludf.DUMMYFUNCTION("""COMPUTED_VALUE"""),"FWC7") -> FWC7 | B9: =IFERROR(__xludf.DUMMYFUNCTION("""COMPUTED_VALUE"""),"SECTION 1") -> SECTION 1 | C9: =IFERROR(__xludf.DUMMYFUNCTION("""COMPUTED_VALUE"""),"SPECIAL") -> SPECIAL | D9: =IFERROR(__xludf.DUMMYFUNCTION("""COMPUTED_VALUE"""),"FWC 7") -> FWC 7 | E9: =IFERROR(__xludf.DUMMYFUNCTION("""COMPUTED_VALUE"""),0.0) -> 0
A10: =IFERROR(__xludf.DUMMYFUNCTION("""COMPUTED_VALUE"""),"FWC8") -> FWC8 | B10: =IFERROR(__xludf.DUMMYFUNCTION("""COMPUTED_VALUE"""),"SECTION 1") -> SECTION 1 | C10: =IFERROR(__xludf.DUMMYFUNCTION("""COMPUTED_VALUE"""),"SPECIAL") -> SPECIAL | D10: =IFERROR(__xludf.DUMMYFUNCTION("""COMPUTED_VALUE"""),"FWC 8") -> FWC 8 | E10: =IFERROR(__xludf.DUMMYFUNCTION("""COMPUTED_VALUE"""),0.0) -> 0
A11: =IFERROR(__xludf.DUMMYFUNCTION("""COMPUTED_VALUE"""),"MEX01") -> MEX01 | B11: =IFERROR(__xludf.DUMMYFUNCTION("""COMPUTED_VALUE"""),"MEXICO") -> MEXICO | C11: =IFERROR(__xludf.DUMMYFUNCTION("""COMPUTED_VALUE"""),"BADGE") -> BADGE | D11: =IFERROR(__xludf.DUMMYFUNCTION("""COMPUTED_VALUE"""),"MEXICO NATIONAL TEAM") -> MEXICO NATIONAL TEAM | E11: =IFERROR(__xludf.DUMMYFUNCTION("""COMPUTED_VALUE"""),0.0) -> 0
A12: =IFERROR(__xludf.DUMMYFUNCTION("""COMPUTED_VALUE"""),"MEX02") -> MEX02 | B12: =IFERROR(__xludf.DUMMYFUNCTION("""COMPUTED_VALUE"""),"MEXICO") -> MEXICO | C12: =IFERROR(__xludf.DUMMYFUNCTION("""COMPUTED_VALUE"""),"NORMAL") -> NORMAL | D12: =IFERROR(__xludf.DUMMYFUNCTION("""COMPUTED_VALUE"""),"LUIS MALAGÓN") -> LUIS MALAGÓN | E12: =IFERROR(__xludf.DUMMYFUNCTION("""COMPUTED_VALUE"""),0.0) -> 0
A13: =IFERROR(__xludf.DUMMYFUNCTION("""COMPUTED_VALUE"""),"MEX03") -> MEX03 | B13: =IFERROR(__xludf.DUMMYFUNCTION("""COMPUTED_VALUE"""),"MEXICO") -> MEXICO | C13: =IFERROR(__xludf.DUMMYFUNCTION("""COMPUTED_VALUE"""),"NORMAL") -> NORMAL | D13: =IFERROR(__xludf.DUMMYFUNCTION("""COMPUTED_VALUE"""),"JOHAN VÁSQUEZ") -> JOHAN VÁSQUEZ | E13: =IFERROR(__xludf.DUMMYFUNCTION("""COMPUTED_VALUE"""),0.0) -> 0
A14: =IFERROR(__xludf.DUMMYFUNCTION("""COMPUTED_VALUE"""),"MEX04") -> MEX04 | B14: =IFERROR(__xludf.DUMMYFUNCTION("""COMPUTED_VALUE"""),"MEXICO") -> MEXICO | C14: =IFERROR(__xludf.DUMMYFUNCTION("""COMPUTED_VALUE"""),"NORMAL") -> NORMAL | D14: =IFERROR(__xludf.DUMMYFUNCTION("""COMPUTED_VALUE"""),"JORGE SÁNCHEZ") -> JORGE SÁNCHEZ | E14: =IFERROR(__xludf.DUMMYFUNCTION("""COMPUTED_VALUE"""),0.0) -> 0
A15: =IFERROR(__xludf.DUMMYFUNCTION("""COMPUTED_VALUE"""),"MEX05") -> MEX05 | B15: =IFERROR(__xludf.DUMMYFUNCTION("""COMPUTED_VALUE"""),"MEXICO") -> MEXICO | C15: =IFERROR(__xludf.DUMMYFUNCTION("""COMPUTED_VALUE"""),"NORMAL") -> NORMAL | D15: =IFERROR(__xludf.DUMMYFUNCTION("""COMPUTED_VALUE"""),"CÉSAR MONTES") -> CÉSAR MONTES | E15: =IFERROR(__xludf.DUMMYFUNCTION("""COMPUTED_VALUE"""),0.0) -> 0
A16: =IFERROR(__xludf.DUMMYFUNCTION("""COMPUTED_VALUE"""),"MEX06") -> MEX06 | B16: =IFERROR(__xludf.DUMMYFUNCTION("""COMPUTED_VALUE"""),"MEXICO") -> MEXICO | C16: =IFERROR(__xludf.DUMMYFUNCTION("""COMPUTED_VALUE"""),"NORMAL") -> NORMAL | D16: =IFERROR(__xludf.DUMMYFUNCTION("""COMPUTED_VALUE"""),"JESÚS GALLARDO") -> JESÚS GALLARDO | E16: =IFERROR(__xludf.DUMMYFUNCTION("""COMPUTED_VALUE"""),0.0) -> 0
A17: =IFERROR(__xludf.DUMMYFUNCTION("""COMPUTED_VALUE"""),"MEX07") -> MEX07 | B17: =IFERROR(__xludf.DUMMYFUNCTION("""COMPUTED_VALUE"""),"MEXICO") -> MEXICO | C17: =IFERROR(__xludf.DUMMYFUNCTION("""COMPUTED_VALUE"""),"NORMAL") -> NORMAL | D17: =IFERROR(__xludf.DUMMYFUNCTION("""COMPUTED_VALUE"""),"ISRAEL REYES") -> ISRAEL REYES | E17: =IFERROR(__xludf.DUMMYFUNCTION("""COMPUTED_VALUE"""),0.0) -> 0
A18: =IFERROR(__xludf.DUMMYFUNCTION("""COMPUTED_VALUE"""),"MEX08") -> MEX08 | B18: =IFERROR(__xludf.DUMMYFUNCTION("""COMPUTED_VALUE"""),"MEXICO") -> MEXICO | C18: =IFERROR(__xludf.DUMMYFUNCTION("""COMPUTED_VALUE"""),"NORMAL") -> NORMAL | D18: =IFERROR(__xludf.DUMMYFUNCTION("""COMPUTED_VALUE"""),"DIEGO LAINEZ") -> DIEGO LAINEZ | E18: =IFERROR(__xludf.DUMMYFUNCTION("""COMPUTED_VALUE"""),0.0) -> 0
A19: =IFERROR(__xludf.DUMMYFUNCTION("""COMPUTED_VALUE"""),"MEX09") -> MEX09 | B19: =IFERROR(__xludf.DUMMYFUNCTION("""COMPUTED_VALUE"""),"MEXICO") -> MEXICO | C19: =IFERROR(__xludf.DUMMYFUNCTION("""COMPUTED_VALUE"""),"NORMAL") -> NORMAL | D19: =IFERROR(__xludf.DUMMYFUNCTION("""COMPUTED_VALUE"""),"CARLOS RODRÍGUEZ") -> CARLOS RODRÍGUEZ | E19: =IFERROR(__xludf.DUMMYFUNCTION("""COMPUTED_VALUE"""),0.0) -> 0
A20: =IFERROR(__xludf.DUMMYFUNCTION("""COMPUTED_VALUE"""),"MEX10") -> MEX10 | B20: =IFERROR(__xludf.DUMMYFUNCTION("""COMPUTED_VALUE"""),"MEXICO") -> MEXICO | C20: =IFERROR(__xludf.DUMMYFUNCTION("""COMPUTED_VALUE"""),"NORMAL") -> NORMAL | D20: =IFERROR(__xludf.DUMMYFUNCTION("""COMPUTED_VALUE"""),"EDSON ÁLVAREZ") -> EDSON ÁLVAREZ | E20: =IFERROR(__xludf.DUMMYFUNCTION("""COMPUTED_VALUE"""),0.0) -> 0
A21: =IFERROR(__xludf.DUMMYFUNCTION("""COMPUTED_VALUE"""),"MEX11") -> MEX11 | B21: =IFERROR(__xludf.DUMMYFUNCTION("""COMPUTED_VALUE"""),"MEXICO") -> MEXICO | C21: =IFERROR(__xludf.DUMMYFUNCTION("""COMPUTED_VALUE"""),"NORMAL") -> NORMAL | D21: =IFERROR(__xludf.DUMMYFUNCTION("""COMPUTED_VALUE"""),"ORBELÍN PINEDA") -> ORBELÍN PINEDA | E21: =IFERROR(__xludf.DUMMYFUNCTION("""COMPUTED_VALUE"""),0.0) -> 0
A22: =IFERROR(__xludf.DUMMYFUNCTION("""COMPUTED_VALUE"""),"MEX12") -> MEX12 | B22: =IFERROR(__xludf.DUMMYFUNCTION("""COMPUTED_VALUE"""),"MEXICO") -> MEXICO | C22: =IFERROR(__xludf.DUMMYFUNCTION("""COMPUTED_VALUE"""),"NORMAL") -> NORMAL | D22: =IFERROR(__xludf.DUMMYFUNCTION("""COMPUTED_VALUE"""),"MARCEL RUÍZ") -> MARCEL RUÍZ | E22: =IFERROR(__xludf.DUMMYFUNCTION("""COMPUTED_VALUE"""),0.0) -> 0
A23: =IFERROR(__xludf.DUMMYFUNCTION("""COMPUTED_VALUE"""),"MEX13") -> MEX13 | B23: =IFERROR(__xludf.DUMMYFUNCTION("""COMPUTED_VALUE"""),"MEXICO") -> MEXICO | C23: =IFERROR(__xludf.DUMMYFUNCTION("""COMPUTED_VALUE"""),"TEAM") -> TEAM | D23: =IFERROR(__xludf.DUMMYFUNCTION("""COMPUTED_VALUE"""),"MEXICO NATIONAL TEAM") -> MEXICO NATIONAL TEAM | E23: =IFERROR(__xludf.DUMMYFUNCTION("""COMPUTED_VALUE"""),0.0) -> 0
A24: =IFERROR(__xludf.DUMMYFUNCTION("""COMPUTED_VALUE"""),"MEX14") -> MEX14 | B24: =IFERROR(__xludf.DUMMYFUNCTION("""COMPUTED_VALUE"""),"MEXICO") -> MEXICO | C24: =IFERROR(__xludf.DUMMYFUNCTION("""COMPUTED_VALUE"""),"NORMAL") -> NORMAL | D24: =IFERROR(__xludf.DUMMYFUNCTION("""COMPUTED_VALUE"""),"ERICK SÁNCHEZ") -> ERICK SÁNCHEZ | E24: =IFERROR(__xludf.DUMMYFUNCTION("""COMPUTED_VALUE"""),0.0) -> 0
A25: =IFERROR(__xludf.DUMMYFUNCTION("""COMPUTED_VALUE"""),"MEX15") -> MEX15 | B25: =IFERROR(__xludf.DUMMYFUNCTION("""COMPUTED_VALUE"""),"MEXICO") -> MEXICO | C25: =IFERROR(__xludf.DUMMYFUNCTION("""COMPUTED_VALUE"""),"NORMAL") -> NORMAL | D25: =IFERROR(__xludf.DUMMYFUNCTION("""COMPUTED_VALUE"""),"HIRVING LOZANO") -> HIRVING LOZANO | E25: =IFERROR(__xludf.DUMMYFUNCTION("""COMPUTED_VALUE"""),0.0) -> 0
A26: =IFERROR(__xludf.DUMMYFUNCTION("""COMPUTED_VALUE"""),"MEX16") -> MEX16 | B26: =IFERROR(__xludf.DUMMYFUNCTION("""COMPUTED_VALUE"""),"MEXICO") -> MEXICO | C26: =IFERROR(__xludf.DUMMYFUNCTION("""COMPUTED_VALUE"""),"NORMAL") -> NORMAL | D26: =IFERROR(__xludf.DUMMYFUNCTION("""COMPUTED_VALUE"""),"SANTIAGO GIMÉNEZ") -> SANTIAGO GIMÉNEZ | E26: =IFERROR(__xludf.DUMMYFUNCTION("""COMPUTED_VALUE"""),0.0) -> 0
A27: =IFERROR(__xludf.DUMMYFUNCTION("""COMPUTED_VALUE"""),"MEX17") -> MEX17 | B27: =IFERROR(__xludf.DUMMYFUNCTION("""COMPUTED_VALUE"""),"MEXICO") -> MEXICO | C27: =IFERROR(__xludf.DUMMYFUNCTION("""COMPUTED_VALUE"""),"NORMAL") -> NORMAL | D27: =IFERROR(__xludf.DUMMYFUNCTION("""COMPUTED_VALUE"""),"RAÚL JIMÉNEZ") -> RAÚL JIMÉNEZ | E27: =IFERROR(__xludf.DUMMYFUNCTION("""COMPUTED_VALUE"""),0.0) -> 0
A28: =IFERROR(__xludf.DUMMYFUNCTION("""COMPUTED_VALUE"""),"MEX18") -> MEX18 | B28: =IFERROR(__xludf.DUMMYFUNCTION("""COMPUTED_VALUE"""),"MEXICO") -> MEXICO | C28: =IFERROR(__xludf.DUMMYFUNCTION("""COMPUTED_VALUE"""),"NORMAL") -> NORMAL | D28: =IFERROR(__xludf.DUMMYFUNCTION("""COMPUTED_VALUE"""),"ALEXIS VEGA") -> ALEXIS VEGA | E28: =IFERROR(__xludf.DUMMYFUNCTION("""COMPUTED_VALUE"""),0.0) -> 0
A29: =IFERROR(__xludf.DUMMYFUNCTION("""COMPUTED_VALUE"""),"MEX19") -> MEX19 | B29: =IFERROR(__xludf.DUMMYFUNCTION("""COMPUTED_VALUE"""),"MEXICO") -> MEXICO | C29: =IFERROR(__xludf.DUMMYFUNCTION("""COMPUTED_VALUE"""),"NORMAL") -> NORMAL | D29: =IFERROR(__xludf.DUMMYFUNCTION("""COMPUTED_VALUE"""),"ROBERTO ALVARADO") -> ROBERTO ALVARADO | E29: =IFERROR(__xludf.DUMMYFUNCTION("""COMPUTED_VALUE"""),0.0) -> 0
A30: =IFERROR(__xludf.DUMMYFUNCTION("""COMPUTED_VALUE"""),"MEX20") -> MEX20 | B30: =IFERROR(__xludf.DUMMYFUNCTION("""COMPUTED_VALUE"""),"MEXICO") -> MEXICO | C30: =IFERROR(__xludf.DUMMYFUNCTION("""COMPUTED_VALUE"""),"NORMAL") -> NORMAL | D30: =IFERROR(__xludf.DUMMYFUNCTION("""COMPUTED_VALUE"""),"CÉSAR HUERTA") -> CÉSAR HUERTA | E30: =IFERROR(__xludf.DUMMYFUNCTION("""COMPUTED_VALUE"""),0.0) -> 0
A31: =IFERROR(__xludf.DUMMYFUNCTION("""COMPUTED_VALUE"""),"RSA01") -> RSA01 | B31: =IFERROR(__xludf.DUMMYFUNCTION("""COMPUTED_VALUE"""),"SOUTHAFRICA") -> SOUTHAFRICA | C31: =IFERROR(__xludf.DUMMYFUNCTION("""COMPUTED_VALUE"""),"BADGE") -> BADGE | D31: =IFERROR(__xludf.DUMMYFUNCTION("""COMPUTED_VALUE"""),"SOUTHAFRICA NATIONAL TEAM") -> SOUTHAFRICA NATIONAL TEAM | E31: =IFERROR(__xludf.DUMMYFUNCTION("""COMPUTED_VALUE"""),0.0) -> 0
A32: =IFERROR(__xludf.DUMMYFUNCTION("""COMPUTED_VALUE"""),"RSA02") -> RSA02 | B32: =IFERROR(__xludf.DUMMYFUNCTION("""COMPUTED_VALUE"""),"SOUTHAFRICA") -> SOUTHAFRICA | C32: =IFERROR(__xludf.DUMMYFUNCTION("""COMPUTED_VALUE"""),"NORMAL") -> NORMAL | D32: =IFERROR(__xludf.DUMMYFUNCTION("""COMPUTED_VALUE"""),"RONWEN WILLIAMS") -> RONWEN WILLIAMS | E32: =IFERROR(__xludf.DUMMYFUNCTION("""COMPUTED_VALUE"""),0.0) -> 0
A33: =IFERROR(__xludf.DUMMYFUNCTION("""COMPUTED_VALUE"""),"RSA03") -> RSA03 | B33: =IFERROR(__xludf.DUMMYFUNCTION("""COMPUTED_VALUE"""),"SOUTHAFRICA") -> SOUTHAFRICA | C33: =IFERROR(__xludf.DUMMYFUNCTION("""COMPUTED_VALUE"""),"NORMAL") -> NORMAL | D33: =IFERROR(__xludf.DUMMYFUNCTION("""COMPUTED_VALUE"""),"SIPHO CHAINE") -> SIPHO CHAINE | E33: =IFERROR(__xludf.DUMMYFUNCTION("""COMPUTED_VALUE"""),0.0) -> 0
A34: =IFERROR(__xludf.DUMMYFUNCTION("""COMPUTED_VALUE"""),"RSA04") -> RSA04 | B34: =IFERROR(__xludf.DUMMYFUNCTION("""COMPUTED_VALUE"""),"SOUTHAFRICA") -> SOUTHAFRICA | C34: =IFERROR(__xludf.DUMMYFUNCTION("""COMPUTED_VALUE"""),"NORMAL") -> NORMAL | D34: =IFERROR(__xludf.DUMMYFUNCTION("""COMPUTED_VALUE"""),"AUBREY MODIBA") -> AUBREY MODIBA | E34: =IFERROR(__xludf.DUMMYFUNCTION("""COMPUTED_VALUE"""),0.0) -> 0
A35: =IFERROR(__xludf.DUMMYFUNCTION("""COMPUTED_VALUE"""),"RSA05") -> RSA05 | B35: =IFERROR(__xludf.DUMMYFUNCTION("""COMPUTED_VALUE"""),"SOUTHAFRICA") -> SOUTHAFRICA | C35: =IFERROR(__xludf.DUMMYFUNCTION("""COMPUTED_VALUE"""),"NORMAL") -> NORMAL | D35: =IFERROR(__xludf.DUMMYFUNCTION("""COMPUTED_VALUE"""),"SAMUKELE KABINI") -> SAMUKELE KABINI | E35: =IFERROR(__xludf.DUMMYFUNCTION("""COMPUTED_VALUE"""),0.0) -> 0
A36: =IFERROR(__xludf.DUMMYFUNCTION("""COMPUTED_VALUE"""),"RSA06") -> RSA06 | B36: =IFERROR(__xludf.DUMMYFUNCTION("""COMPUTED_VALUE"""),"SOUTHAFRICA") -> SOUTHAFRICA | C36: =IFERROR(__xludf.DUMMYFUNCTION("""COMPUTED_VALUE"""),"NORMAL") -> NORMAL | D36: =IFERROR(__xludf.DUMMYFUNCTION("""COMPUTED_VALUE"""),"MBEKEZLI MBOKAZI") -> MBEKEZLI MBOKAZI | E36: =IFERROR(__xludf.DUMMYFUNCTION("""COMPUTED_VALUE"""),0.0) -> 0
A37: =IFERROR(__xludf.DUMMYFUNCTION("""COMPUTED_VALUE"""),"RSA07") -> RSA07 | B37: =IFERROR(__xludf.DUMMYFUNCTION("""COMPUTED_VALUE"""),"SOUTHAFRICA") -> SOUTHAFRICA | C37: =IFERROR(__xludf.DUMMYFUNCTION("""COMPUTED_VALUE"""),"NORMAL") -> NORMAL | D37: =IFERROR(__xludf.DUMMYFUNCTION("""COMPUTED_VALUE"""),"KHULUMANI NDAMANE") -> KHULUMANI NDAMANE | E37: =IFERROR(__xludf.DUMMYFUNCTION("""COMPUTED_VALUE"""),0.0) -> 0
A38: =IFERROR(__xludf.DUMMYFUNCTION("""COMPUTED_VALUE"""),"RSA08") -> RSA08 | B38: =IFERROR(__xludf.DUMMYFUNCTION("""COMPUTED_VALUE"""),"SOUTHAFRICA") -> SOUTHAFRICA | C38: =IFERROR(__xludf.DUMMYFUNCTION("""COMPUTED_VALUE"""),"NORMAL") -> NORMAL | D38: =IFERROR(__xludf.DUMMYFUNCTION("""COMPUTED_VALUE"""),"SIVABONGA NGEZANA") -> SIVABONGA NGEZANA | E38: =IFERROR(__xludf.DUMMYFUNCTION("""COMPUTED_VALUE"""),0.0) -> 0
A39: =IFERROR(__xludf.DUMMYFUNCTION("""COMPUTED_VALUE"""),"RSA09") -> RSA09 | B39: =IFERROR(__xludf.DUMMYFUNCTION("""COMPUTED_VALUE"""),"SOUTHAFRICA") -> SOUTHAFRICA | C39: =IFERROR(__xludf.DUMMYFUNCTION("""COMPUTED_VALUE"""),"NORMAL") -> NORMAL | D39: =IFERROR(__xludf.DUMMYFUNCTION("""COMPUTED_VALUE"""),"KHULISO MUDAU") -> KHULISO MUDAU | E39: =IFERROR(__xludf.DUMMYFUNCTION("""COMPUTED_VALUE"""),0.0) -> 0
A40: =IFERROR(__xludf.DUMMYFUNCTION("""COMPUTED_VALUE"""),"RSA10") -> RSA10 | B40: =IFERROR(__xludf.DUMMYFUNCTION("""COMPUTED_VALUE"""),"SOUTHAFRICA") -> SOUTHAFRICA | C40: =IFERROR(__xludf.DUMMYFUNCTION("""COMPUTED_VALUE"""),"NORMAL") -> NORMAL | D40: =IFERROR(__xludf.DUMMYFUNCTION("""COMPUTED_VALUE"""),"NKOSINATHI SIBISI") -> NKOSINATHI SIBISI | E40: =IFERROR(__xludf.DUMMYFUNCTION("""COMPUTED_VALUE"""),0.0) -> 0
...

Sheet TRADING
A1: ID | B1: SECTION | C1: TYPE | D1: PLAYER | E1: QUANTITY
A2: =IFERROR(__xludf.DUMMYFUNCTION("FILTER(MASTER!A2:F1000, MASTER!E2:E1000 > 1)"),"#N/A") -> #N/A
